<mujoco model="kangaroo_grippers">
  <compiler angle="radian" meshdir="../../../../data/assets"/>

  <size nkey="1"/>

  <default>
    <site size="0.01 0.005 0.005" group="5" rgba="1 0 0 1"/>
    <default class="visual">
      <geom type="mesh" contype="0" conaffinity="0" group="2" density="0" material="dark_gray"/>
    </default>
    <default class="collision">
      <geom type="capsule" group="3" material="bright_orange"/>
      <default class="foot_capsule">
        <geom size="0.01 0 0"/>
      </default>
    </default>
  </default>

  <asset>
    <material name="dark_gray" rgba="0.298039 0.298039 0.298039 1"/>
    <material name="bright_orange" rgba="1 0.65 0 0.2"/>
    <mesh name="base_link_with_pelvis" content_type="model/stl" file="base/base_link_with_pelvis.STL"/>
    <mesh name="handle" content_type="model/stl" file="base/handle.STL"/>
    <mesh name="pelvis_base_link" content_type="model/stl" file="pelvis/pelvis_base_link.STL"/>
    <mesh name="pelvis_1_link" content_type="model/stl" file="pelvis/pelvis_1_link.STL"/>
    <mesh name="pelvis_2_link" content_type="model/stl" file="pelvis/pelvis_2_link.STL"/>
    <mesh name="torso_link" content_type="model/stl" file="torso/torso_link.STL"/>
    <mesh name="leg_left_1_link" content_type="model/stl" file="leg/leg_left_1_link.STL"/>
    <mesh name="leg_left_2_link" content_type="model/stl" file="leg/leg_left_2_link.STL"/>
    <mesh name="leg_left_3_link" content_type="model/stl" file="leg/leg_left_3_link.STL"/>
    <mesh name="leg_6_link" content_type="model/stl" file="leg/leg_left_6_link.STL"/>
    <mesh name="leg_7_link" content_type="model/stl" file="leg/leg_left_7_link.STL"/>
    <mesh name="leg_right_1_link" content_type="model/stl" file="leg/leg_right_1_link.STL"/>
    <mesh name="leg_right_2_link" content_type="model/stl" file="leg/leg_right_2_link.STL"/>
    <mesh name="leg_right_3_link" content_type="model/stl" file="leg/leg_right_3_link.STL"/>
    <mesh name="leg_6_link1" content_type="model/stl" file="leg/leg_right_6_link.STL"/>
    <mesh name="leg_7_link1" content_type="model/stl" file="leg/leg_right_7_link.STL"/>
    <mesh name="leg_femur_link" content_type="model/stl" file="leg/leg_femur_link.STL"/>
    <mesh name="leg_tibia_link" content_type="model/stl" file="leg/leg_tibia_link.STL"/>
    <mesh name="arm_base_link" content_type="model/stl" file="arm/arm_base_link.STL"/>
    <mesh name="arm1_link" content_type="model/stl" file="arm/arm1_link.STL"/>
    <mesh name="arm2_link" content_type="model/stl" file="arm/arm2_link.STL"/>
    <mesh name="arm3_link" content_type="model/stl" file="arm/arm3_link.STL"/>
    <mesh name="arm4_link" content_type="model/stl" file="arm/arm4_link.STL"/>
    <mesh name="arm5_link" content_type="model/stl" file="arm/arm5_link.STL"/>
    <mesh name="arm6_link" content_type="model/stl" file="arm/arm6_link.STL"/>
    <mesh name="arm7_link" content_type="model/stl" file="arm/arm7_link.STL"/>
    <mesh name="base_link_tc" content_type="model/stl" file="gripper/base_link_tc.STL"/>
    <mesh name="inner_finger" content_type="model/stl" file="gripper/inner_finger.STL"/>
    <mesh name="outer_finger" content_type="model/stl" file="gripper/outer_finger.STL"/>
    <mesh name="fingertip" content_type="model/stl" file="gripper/fingertip.STL"/>
  </asset>

  <worldbody>
    <body name="base_link" pos="0 0 0.9">
      <inertial pos="-0.0913441 -0.0013598 0.00676412" quat="0.5 0.5 -0.5 0.5" mass="4.82254" diaginertia="0.0600103 0.0509711 0.0269078"/>
      <joint name="origin" type="free"/>
      <geom class="visual" mesh="base_link_with_pelvis"/>
      <geom class="visual" mesh="handle"/>
      <geom class="visual" pos="-0.0918 0 -0.0455" quat="1 0 0 0" mesh="pelvis_base_link"/>
      <camera name="front_view" pos="5 0 0.5" quat="0.561004 0.430435 0.430435 0.561004" mode="track"/>
      <body name="pelvis_1_link" pos="-0.0918 0 0.0065" quat="0.707105 0 0.707108 0">
        <inertial pos="-0.02593 -1e-06 0.001466" quat="0.99984 0 -0.0179004 0" mass="1.24856" diaginertia="0.00539676 0.004808 0.00324424"/>
        <joint name="pelvis_1_joint" pos="0 0 0" axis="0 0 -1" range="-0.349066 0.349066" armature="0.0126498"/>
        <geom class="visual" mesh="pelvis_1_link"/>
        <body name="pelvis_2_link" pos="-0.0591 0 0" quat="0.707105 0 -0.707108 0">
          <inertial pos="-0.0096298 -0.000857135 0.220739" quat="0.999875 0.0105643 0.00161433 -0.0116448" mass="13.7723" diaginertia="0.312791 0.291456 0.113386"/>
          <joint name="pelvis_2_joint" pos="0 0 0" axis="0 0 -1" range="-1.309 1.309" armature="0.0126498"/>
          <geom class="visual" mesh="pelvis_2_link"/>
          <geom class="visual" pos="0 0 0.0061" quat="1 0 0 0" mesh="torso_link"/>
          <geom class="visual" pos="0 0.105954 0.390496" quat="0.642802 -0.766033 1.86923e-06 1.63502e-07" mesh="arm_base_link"/>
          <geom class="visual" pos="0 -0.105954 0.390496" quat="1.01637e-06 8.52866e-07 0.766033 -0.642802" mesh="arm_base_link"/>
          <geom name="pelvis_2_collision" class="collision" size="0.163724 0.162985" pos="4.77798e-07 -1.67441e-06 0.234507" quat="1 -3.97075e-06 -1.19191e-05 0" contype="0" conaffinity="0"/>
          <site name="imu" pos="0.071 -0.0014 0.0261" quat="0 -0.707107 0.707107 0"/>
          <body name="arm_left_1_link" pos="0 0.105954 0.390496" quat="-4.68302e-06 -2.52466e-06 0.642799 -0.766035">
            <inertial pos="0.0070639 0.0030301 -0.05724" quat="0.991252 0.0809813 -0.0910271 0.0507521" mass="1.1788" diaginertia="0.00192068 0.00177268 0.000875278"/>
            <joint name="arm_left_1_joint" pos="0 0 0" axis="0 0 -1" range="-2.61799 2.61799" armature="0.0126498"/>
            <geom class="visual" mesh="arm1_link"/>
            <body name="arm_left_2_link" pos="0.03711 0.02 -0.17011" quat="0.707105 0 0.707108 0">
              <inertial pos="0.029543 -0.0049762 -0.03224" quat="0.0848392 0.690549 -0.0139433 0.718157" mass="1.2955" diaginertia="0.00278545 0.00260446 0.00100708"/>
              <joint name="arm_left_2_joint" pos="0 0 0" axis="0 0 1" range="-1.13446 2.44346" armature="0.0126498"/>
              <geom class="visual" mesh="arm2_link"/>
              <body name="arm_left_3_link" pos="0.15989 -0.02 -0.03711" quat="0.707105 0 -0.707108 0">
                <inertial pos="-0.00706385 -0.00303013 -0.0572396" quat="0.991251 -0.0809737 0.0910312 0.0507756" mass="1.17879" diaginertia="0.00192065 0.00177272 0.000875276"/>
                <joint name="arm_left_3_joint" pos="0 0 0" axis="0 0 -1" range="-2.61799 2.61799" armature="0.00663065"/>
                <geom class="visual" mesh="arm3_link"/>
                <body name="arm_left_4_link" pos="-0.03711 -0.02 -0.17011" quat="0.707105 0 -0.707108 0">
                  <inertial pos="-0.0666639 0.0102985 -0.0351108" quat="0.0552758 0.727273 -0.0700841 0.68052" mass="1.80676" diaginertia="0.00263554 0.00245424 0.00145523"/>
                  <joint name="arm_left_4_joint" pos="0 0 0" axis="0 0 1" range="-1.13446 2.44346" armature="0.00663065"/>
                  <geom class="visual" mesh="arm4_link"/>
                  <geom name="arm_left_4_collision" class="collision" size="0.07 0.15" pos="-0.15 0 -0.05" quat="0.707107 0 -0.707107 0" contype="0" conaffinity="0"/>
                  <body name="arm_left_5_link" pos="-0.17011 0.02 -0.03711" quat="0.707105 0 -0.707108 0">
                    <inertial pos="0.0266059 -9.73534e-06 0.0673257" quat="0.989898 -7.96043e-05 0.141782 -0.000384017" mass="0.348015" diaginertia="0.0015535 0.0014601 0.000311872"/>
                    <joint name="arm_left_5_joint" pos="0 0 0" axis="0 0 1" range="-2.61799 2.61799" armature="0.00663065"/>
                    <geom type="mesh" contype="0" conaffinity="0" group="1" density="0" rgba="0.298039 0.298039 0.298039 1" mesh="arm5_link"/>
                    <body name="arm_left_6_link" pos="0.0422 0 0.1654" quat="0.707105 0 0.707108 0">
                      <inertial pos="-0.00626817 -0.0318124 -0.0405314" quat="0.663771 0.673523 -0.178424 -0.27192" mass="1.39009" diaginertia="0.00126764 0.00121953 0.00102842"/>
                      <joint name="arm_left_6_joint" pos="0 0 0" axis="0 0 -1" range="-1.88496 3.00197" armature="0.00663065"/>
                      <geom type="mesh" contype="0" conaffinity="0" group="1" density="0" rgba="0.298039 0.298039 0.298039 1" mesh="arm6_link"/>
                      <body name="arm_left_7_link" pos="-0.0534 -0.07 -0.0422" quat="0.707105 0 -0.707108 0">
                        <inertial pos="0.000145329 0.000246068 0.0490178" quat="0.99991 0.00738555 -0.00687251 0.00884821" mass="0.762485" diaginertia="0.00104577 0.00101366 0.000480656"/>
                        <joint name="arm_left_7_joint" pos="0 0 0" axis="0 0 1" range="-2.61799 2.61799" armature="0.00663065"/>
                        <geom type="mesh" contype="0" conaffinity="0" group="1" density="0" rgba="0.298039 0.298039 0.298039 1" mesh="arm7_link"/>
                        <geom pos="0 0 0.017" quat="0.707388 0 0 -0.706825" type="mesh" contype="0" conaffinity="0" group="1" density="0" rgba="0.298039 0.298039 0.298039 1" mesh="base_link_tc"/>
                        <site name="ee_left" pos="0 0 0"/>
                        <body name="gripper_left_inner_finger_left_link" pos="-0.013977 -1.11303e-05 0.095832" quat="-0.287351 0.287862 -0.645861 -0.646087">
                          <inertial pos="0 0.024759 0" quat="0.5 0.5 -0.5 0.5" mass="0.018619" diaginertia="4.9573e-06 4.8806e-06 2.5471e-07"/>
                          <geom type="mesh" contype="0" conaffinity="0" group="1" density="0" rgba="0.752941 0.752941 0.752941 1" mesh="inner_finger"/>
                          <body name="gripper_left_fingertip_left_link" pos="0 0.05 0" quat="0.913545 0 0 0.406738">
                            <inertial pos="-0.000864586 0.011929 -2.73244e-11" quat="0.704565 0.704565 0.0599056 0.0599056" mass="0.033503" diaginertia="3.69751e-06 2.84428e-06 1.65117e-06"/>
                            <geom type="mesh" contype="0" conaffinity="0" group="1" density="0" rgba="0.752941 0.752941 0.752941 1" mesh="fingertip"/>
                          </body>
                        </body>
                        <body name="gripper_left_outer_finger_left_link" pos="-0.0288 -2.29342e-05 0.0913" quat="-0.287351 0.287862 -0.645861 -0.646087">
                          <inertial pos="-0.00128298 0.0143975 0" quat="0.522876 0.476026 -0.522876 0.476026" mass="0.0159888" diaginertia="6.14973e-06 6.03691e-06 4.38203e-07"/>
                          <geom type="mesh" contype="0" conaffinity="0" group="1" density="0" rgba="0.752941 0.752941 0.752941 1" mesh="outer_finger"/>
                        </body>
                        <body name="gripper_left_inner_finger_right_link" pos="0.013977 1.11303e-05 0.095832" quat="0.646088 0.64586 0.287865 -0.287349">
                          <inertial pos="0 0.024759 0" quat="0.5 0.5 -0.5 0.5" mass="0.018619" diaginertia="4.9573e-06 4.8806e-06 2.5471e-07"/>
                          <geom type="mesh" contype="0" conaffinity="0" group="1" density="0" rgba="0.752941 0.752941 0.752941 1" mesh="inner_finger"/>
                          <body name="gripper_left_fingertip_right_link" pos="0 0.05 0" quat="0.913545 0 0 0.406738">
                            <inertial pos="-0.000864586 0.011929 -2.73244e-11" quat="0.704565 0.704565 0.0599056 0.0599056" mass="0.033503" diaginertia="3.69751e-06 2.84428e-06 1.65117e-06"/>
                            <geom type="mesh" contype="0" conaffinity="0" group="1" density="0" rgba="0.752941 0.752941 0.752941 1" mesh="fingertip"/>
                          </body>
                        </body>
                        <body name="gripper_left_outer_finger_right_link" pos="0.0288 2.29342e-05 0.0913" quat="0.646088 0.64586 0.287865 -0.287349">
                          <inertial pos="-0.00128298 0.0143975 0" quat="0.522876 0.476026 -0.522876 0.476026" mass="0.0159888" diaginertia="6.14973e-06 6.03691e-06 4.38203e-07"/>
                          <geom type="mesh" contype="0" conaffinity="0" group="1" density="0" rgba="0.752941 0.752941 0.752941 1" mesh="outer_finger"/>
                        </body>
                      </body>
                    </body>
                  </body>
                </body>
              </body>
            </body>
          </body>
          <body name="arm_right_1_link" pos="0 -0.105954 0.390496" quat="-0.766035 0.642799 3.37752e-06 3.66665e-06">
            <inertial pos="0.0070639 0.0030301 -0.05724" quat="0.991252 0.0809813 -0.0910271 0.0507521" mass="1.1788" diaginertia="0.00192068 0.00177268 0.000875278"/>
            <joint name="arm_right_1_joint" pos="0 0 0" axis="0 0 -1" range="-2.61799 2.61799" armature="0.0126498"/>
            <geom class="visual" mesh="arm1_link"/>
            <body name="arm_right_2_link" pos="0.03711 0.02 -0.17011" quat="0.707105 0 0.707108 0">
              <inertial pos="0.029543 -0.0049762 -0.03224" quat="0.0848392 0.690549 -0.0139433 0.718157" mass="1.2955" diaginertia="0.00278545 0.00260446 0.00100708"/>
              <joint name="arm_right_2_joint" pos="0 0 0" axis="0 0 1" range="-1.13446 2.44346" armature="0.0126498"/>
              <geom class="visual" mesh="arm2_link"/>
              <body name="arm_right_3_link" pos="0.15989 -0.02 -0.03711" quat="0.707105 0 -0.707108 0">
                <inertial pos="-0.00706385 -0.00303013 -0.0572396" quat="0.991251 -0.0809737 0.0910312 0.0507756" mass="1.17879" diaginertia="0.00192065 0.00177272 0.000875276"/>
                <joint name="arm_right_3_joint" pos="0 0 0" axis="0 0 -1" range="-2.61799 2.61799" armature="0.00663065"/>
                <geom class="visual" mesh="arm3_link"/>
                <body name="arm_right_4_link" pos="-0.03711 -0.02 -0.17011" quat="0.707105 0 -0.707108 0">
                  <inertial pos="-0.0666639 0.0102985 -0.0351108" quat="0.0552758 0.727273 -0.0700841 0.68052" mass="1.80676" diaginertia="0.00263554 0.00245424 0.00145523"/>
                  <joint name="arm_right_4_joint" pos="0 0 0" axis="0 0 1" range="-1.13446 2.44346" armature="0.00663065"/>
                  <geom class="visual" mesh="arm4_link"/>
                  <geom name="arm_right_4_collision" class="collision" size="0.07 0.15" pos="-0.15 0 -0.05" quat="0.707107 0 -0.707107 0" contype="0" conaffinity="0"/>
                  <body name="arm_right_5_link" pos="-0.17011 0.02 -0.03711" quat="0.707105 0 -0.707108 0">
                    <inertial pos="0.0266059 -9.73534e-06 0.0673257" quat="0.989898 -7.96043e-05 0.141782 -0.000384017" mass="0.348015" diaginertia="0.0015535 0.0014601 0.000311872"/>
                    <joint name="arm_right_5_joint" pos="0 0 0" axis="0 0 1" range="-2.61799 2.61799" armature="0.00663065"/>
                    <geom type="mesh" contype="0" conaffinity="0" group="1" density="0" rgba="0.298039 0.298039 0.298039 1" mesh="arm5_link"/>
                    <body name="arm_right_6_link" pos="0.0422 0 0.1654" quat="0.707105 0 0.707108 0">
                      <inertial pos="-0.00626817 -0.0318124 -0.0405314" quat="0.663771 0.673523 -0.178424 -0.27192" mass="1.39009" diaginertia="0.00126764 0.00121953 0.00102842"/>
                      <joint name="arm_right_6_joint" pos="0 0 0" axis="0 0 -1" range="-1.88496 3.00197" armature="0.00663065"/>
                      <geom type="mesh" contype="0" conaffinity="0" group="1" density="0" rgba="0.298039 0.298039 0.298039 1" mesh="arm6_link"/>
                      <body name="arm_right_7_link" pos="-0.0534 -0.07 -0.0422" quat="0.707105 0 -0.707108 0">
                        <inertial pos="0.000145329 0.000246068 0.0490178" quat="0.99991 0.00738555 -0.00687251 0.00884821" mass="0.762485" diaginertia="0.00104577 0.00101366 0.000480656"/>
                        <joint name="arm_right_7_joint" pos="0 0 0" axis="0 0 1" range="-2.61799 2.61799" armature="0.00663065"/>
                        <geom type="mesh" contype="0" conaffinity="0" group="1" density="0" rgba="0.298039 0.298039 0.298039 1" mesh="arm7_link"/>
                        <geom pos="0 0 0.017" quat="0.707388 0 0 -0.706825" type="mesh" contype="0" conaffinity="0" group="1" density="0" rgba="0.298039 0.298039 0.298039 1" mesh="base_link_tc"/>
                        <site name="ee_right" pos="0 0 0"/>
                        <body name="gripper_right_inner_finger_left_link" pos="-0.013977 -1.11303e-05 0.095832" quat="-0.287351 0.287862 -0.645861 -0.646087">
                          <inertial pos="0 0.024759 0" quat="0.5 0.5 -0.5 0.5" mass="0.018619" diaginertia="4.9573e-06 4.8806e-06 2.5471e-07"/>
                          <geom type="mesh" contype="0" conaffinity="0" group="1" density="0" rgba="0.752941 0.752941 0.752941 1" mesh="inner_finger"/>
                          <body name="gripper_right_fingertip_left_link" pos="0 0.05 0" quat="0.913545 0 0 0.406738">
                            <inertial pos="-0.000864586 0.011929 -2.73244e-11" quat="0.704565 0.704565 0.0599056 0.0599056" mass="0.033503" diaginertia="3.69751e-06 2.84428e-06 1.65117e-06"/>
                            <geom type="mesh" contype="0" conaffinity="0" group="1" density="0" rgba="0.752941 0.752941 0.752941 1" mesh="fingertip"/>
                          </body>
                        </body>
                        <body name="gripper_right_outer_finger_left_link" pos="-0.0288 -2.29342e-05 0.0913" quat="-0.287351 0.287862 -0.645861 -0.646087">
                          <inertial pos="-0.00128298 0.0143975 0" quat="0.522876 0.476026 -0.522876 0.476026" mass="0.0159888" diaginertia="6.14973e-06 6.03691e-06 4.38203e-07"/>
                          <geom type="mesh" contype="0" conaffinity="0" group="1" density="0" rgba="0.752941 0.752941 0.752941 1" mesh="outer_finger"/>
                        </body>
                        <body name="gripper_right_inner_finger_right_link" pos="0.013977 1.11303e-05 0.095832" quat="0.646088 0.64586 0.287865 -0.287349">
                          <inertial pos="0 0.024759 0" quat="0.5 0.5 -0.5 0.5" mass="0.018619" diaginertia="4.9573e-06 4.8806e-06 2.5471e-07"/>
                          <geom type="mesh" contype="0" conaffinity="0" group="1" density="0" rgba="0.752941 0.752941 0.752941 1" mesh="inner_finger"/>
                          <body name="gripper_right_fingertip_right_link" pos="0 0.05 0" quat="0.913545 0 0 0.406738">
                            <inertial pos="-0.000864586 0.011929 -2.73244e-11" quat="0.704565 0.704565 0.0599056 0.0599056" mass="0.033503" diaginertia="3.69751e-06 2.84428e-06 1.65117e-06"/>
                            <geom type="mesh" contype="0" conaffinity="0" group="1" density="0" rgba="0.752941 0.752941 0.752941 1" mesh="fingertip"/>
                          </body>
                        </body>
                        <body name="gripper_right_outer_finger_right_link" pos="0.0288 2.29342e-05 0.0913" quat="0.646088 0.64586 0.287865 -0.287349">
                          <inertial pos="-0.00128298 0.0143975 0" quat="0.522876 0.476026 -0.522876 0.476026" mass="0.0159888" diaginertia="6.14973e-06 6.03691e-06 4.38203e-07"/>
                          <geom type="mesh" contype="0" conaffinity="0" group="1" density="0" rgba="0.752941 0.752941 0.752941 1" mesh="outer_finger"/>
                        </body>
                      </body>
                    </body>
                  </body>
                </body>
              </body>
            </body>
          </body>
        </body>
      </body>
      <body name="leg_left_1_link" pos="-0.0150026 0.08 -0.0585">
        <inertial pos="0.0063167 0.0045949 -0.0083828" quat="0.99829 -0.0115969 -0.0468646 0.0329665" mass="2.7478" diaginertia="0.00193869 0.00182214 0.00142127"/>
        <joint name="leg_left_1_joint" pos="0 0 0" axis="0 0 1" range="-0.261799 0.698132" armature="0.01"/>
        <geom class="visual" mesh="leg_left_1_link"/>
        <geom name="leg_left1_1_collision" class="collision" size="0.04 0.0075" pos="0.07 -0.035 -0.0225" quat="0 1 0 0" contype="0" conaffinity="0"/>
        <body name="leg_left_2_link" pos="0.015024 0 -0.1175">
          <inertial pos="-0.0029278 -9.6207e-05 1.0866e-09" quat="0.500354 0.500354 0.499645 0.499645" mass="0.0905312" diaginertia="3.88542e-05 3.62287e-05 6.1016e-06"/>
          <joint name="leg_left_2_joint" pos="0 0 0" axis="0 1 0" range="-0.741765 0.663225" armature="0.01"/>
          <geom class="visual" mesh="leg_left_2_link"/>
          <body name="leg_left_3_link">
            <inertial pos="-0.033949 0.049989 -0.030543" quat="0.0645597 0.615939 -0.131914 0.773983" mass="3.658" diaginertia="0.00327114 0.00320831 0.00250706"/>
            <joint name="leg_left_3_joint" pos="0 0 0" axis="1 0 0" range="-0.471239 0.471239" armature="0.01"/>
            <geom class="visual" mesh="leg_left_3_link"/>
            <body name="leg_left_length_link" pos="0 0.0669 -0.09" quat="0 0 1 0">
              <inertial pos="0 0 0" mass="0.1" diaginertia="8.58333e-05 8.58333e-05 5e-06"/>
              <joint name="leg_left_length_joint" pos="0 0 0" axis="0 0 1" type="slide" range="0.131973 0.714166" armature="0.01"/>
              <geom class="visual" size="5e-05 0.291097" pos="0 0 -0.291097" type="cylinder"/>
              <body name="leg_left_4_link" quat="-0.173648 0 0.984808 0">
                <inertial pos="-0.00759995 -6.94998e-09 5.88281e-08" quat="3.61787e-06 0.707107 3.61787e-06 0.707106" mass="0.0905838" diaginertia="2.98863e-05 2.92763e-05 4.05264e-06"/>
                <joint name="leg_left_4_joint" pos="0 0 0" axis="0 1 0" range="-0.741765 0.663225" armature="0.01"/>
                <geom class="visual" quat="0.984808 0 -0.173648 0" mesh="leg_6_link"/>
                <body name="leg_left_5_link">
                  <inertial pos="0.00560127 -5.98529e-06 -0.0297244" quat="-8.95501e-06 0.58162 -1.58775e-05 0.813461" mass="0.61563" diaginertia="0.0019868 0.00170803 0.000338695"/>
                  <joint name="leg_left_5_joint" pos="0 0 0" axis="-1 0 0" range="-0.471239 0.471239" armature="0.01"/>
                  <geom class="visual" mesh="leg_7_link"/>
                  <site name="left_foot" pos="0.0575 0 -0.0243" size="0.015"/>
                  <body name="leg_left_foot_link" pos="0 0 -0.034" quat="0.984808 0 -0.173648 0">
                    <geom name="left_foot0_collision" class="foot_capsule" size="0.01 0.0965052" pos="0.0135 -0.034 0" quat="0.707107 0.00732714 -0.707069 0" contype="0" priority="1" friction="0.6"/>
                    <geom name="left_foot2_collision" class="foot_capsule" size="0.01 0.10875" pos="0.01125 -0.02125 0" quat="0.707107 -0.00162553 -0.707105 0" contype="0" priority="1" friction="0.6"/>
                    <geom name="left_foot4_collision" class="foot_capsule" size="0.01 0.11025" pos="0.01175 -0.00675 0" quat="0.707107 0.00160341 -0.707105 0" contype="0" priority="1" friction="0.6"/>
                    <geom name="left_foot6_collision" class="foot_capsule" size="0.01 0.11025" pos="0.01175 0.00675 0" quat="0.707107 -0.00160341 -0.707105 0" contype="0" priority="1" friction="0.6"/>
                    <geom name="left_foot8_collision" class="foot_capsule" size="0.01 0.10875" pos="0.01125 0.02125 0" quat="0.707107 0.00162553 -0.707105 0" contype="0" priority="1" friction="0.6"/>
                    <geom name="left_foot10_collision" class="foot_capsule" size="0.01 0.0965052" pos="0.0135 0.034 0" quat="0.707107 -0.00732714 -0.707069 0" contype="0" priority="1" friction="0.6"/>
                    <body name="leg_left_ankle_link">
                      <geom name="leg_left_ankle_collision" class="collision" size="0.03 0.03" pos="-0.01 0 0.03" quat="0.707107 0 -0.707107 0" contype="0" conaffinity="0"/>
                      <geom name="leg_left_ankle_bar_collision" class="collision" size="0.03 0.035" pos="-0.045 0 0.05" quat="0.707107 0.707107 0 0" contype="0" conaffinity="0"/>
                    </body>
                  </body>
                </body>
              </body>
            </body>
            <body name="leg_left_femur_link" pos="0 0.0669 -0.09" quat="0.819152 0 -0.573576 0">
              <inertial pos="0.0527475 0.000135688 -0.146959" quat="0.720223 -0.0942418 -0.0980078 0.680288" mass="3.94567" diaginertia="0.0121138 0.0118241 0.00184947"/>
              <joint name="leg_left_femur_joint" pos="0 0 0" axis="0 1 0" range="0.174533 1.22173"/>
              <geom class="visual" mesh="leg_femur_link"/>
              <geom name="leg_left_femur_collision" class="collision" size="0.0910718 0.2" pos="0.043456 0.000622273 -0.115825" quat="0.194464 0.00344037 0.980904 2.41185e-06" contype="0" conaffinity="0"/>
              <body name="leg_left_knee_link" pos="0.129945 0 -0.357092" quat="0.34202 0 0.939693 0">
                <inertial pos="-0.0569665 -5.4131e-05 -0.148821" quat="0.698616 0.0970713 0.0960701 0.702341" mass="1.02238" diaginertia="0.00215347 0.00207236 0.000258578"/>
                <joint name="leg_left_knee_joint" pos="0 0 0" axis="0 -1 0" range="0.349066 2.44346"/>
                <geom class="visual" mesh="leg_tibia_link"/>
                <geom name="leg_left_knee_collision" class="collision" size="0.04 0.18043" pos="-0.0456 0 -0.15165" quat="0.298159 0 -0.954516 0" contype="0" conaffinity="0"/>
                <geom name="leg_left_knee_bar_collision" class="collision" size="0.05 0.158114" pos="-0.1 0 -0.15" quat="0.987087 0 0.160182 0" contype="0" conaffinity="0"/>
              </body>
            </body>
          </body>
        </body>
      </body>
      <body name="leg_right_1_link" pos="-0.0150026 -0.08 -0.0585">
        <inertial pos="0.0063167 -0.0045949 -0.0083828" quat="0.998081 0.0061833 0.0472134 -0.0395937" mass="2.7478" diaginertia="0.00193889 0.00182188 0.00142133"/>
        <joint name="leg_right_1_joint" pos="0 0 0" axis="0 0 1" range="-0.698132 0.261799" armature="0.01"/>
        <geom class="visual" mesh="leg_right_1_link"/>
        <geom name="leg_right1_1_collision" class="collision" size="0.04 0.0075" pos="0.07 0.035 -0.0225" quat="0 1 0 0" contype="0" conaffinity="0"/>
        <body name="leg_right_2_link" pos="0.015024 0 -0.1175">
          <inertial pos="-0.0029278 -9.6207e-05 1.0866e-09" quat="0.500354 0.500354 0.499645 0.499645" mass="0.0905312" diaginertia="3.88542e-05 3.62287e-05 6.1016e-06"/>
          <joint name="leg_right_2_joint" pos="0 0 0" axis="0 1 0" range="-0.741765 0.663225" armature="0.01"/>
          <geom class="visual" mesh="leg_right_2_link"/>
          <body name="leg_right_3_link">
            <inertial pos="-0.033949 -0.049989 -0.030543" quat="-0.276874 0.75747 -0.131896 0.576353" mass="3.658" diaginertia="0.00331808 0.0031534 0.00251503"/>
            <joint name="leg_right_3_joint" pos="0 0 0" axis="1 0 0" range="-0.471239 0.471239" armature="0.01"/>
            <geom class="visual" mesh="leg_right_3_link"/>
            <body name="leg_right_length_link" pos="0 -0.0669 -0.09" quat="0 0 1 0">
              <inertial pos="0 0 0" mass="0.1" diaginertia="8.58333e-05 8.58333e-05 5e-06"/>
              <joint name="leg_right_length_joint" pos="0 0 0" axis="0 0 1" type="slide" range="0.131973 0.714166" armature="0.01"/>
              <geom class="visual" size="5e-05 0.291097" pos="0 0 -0.291097" type="cylinder"/>
              <body name="leg_right_4_link" quat="-0.173648 0 0.984808 0">
                <inertial pos="-0.00759995 -6.94998e-09 5.88281e-08" quat="3.61787e-06 0.707107 3.61787e-06 0.707106" mass="0.0905838" diaginertia="2.98863e-05 2.92763e-05 4.05264e-06"/>
                <joint name="leg_right_4_joint" pos="0 0 0" axis="0 1 0" range="-0.741765 0.663225" armature="0.01"/>
                <geom class="visual" quat="0.984808 0 -0.173648 0" mesh="leg_6_link"/>
                <body name="leg_right_5_link">
                  <inertial pos="0.00560127 -5.98529e-06 -0.0297244" quat="-8.95501e-06 0.58162 -1.58775e-05 0.813461" mass="0.61563" diaginertia="0.0019868 0.00170803 0.000338695"/>
                  <joint name="leg_right_5_joint" pos="0 0 0" axis="-1 0 0" range="-0.471239 0.471239" armature="0.01"/>
                  <geom class="visual" mesh="leg_7_link"/>
                  <site name="right_foot" pos="0.0575 0 -0.0243" size="0.015"/>
                  <body name="leg_right_foot_link" pos="0 0 -0.034" quat="0.984808 0 -0.173648 0">
                    <geom name="right_foot0_collision" class="foot_capsule" size="0.01 0.0965052" pos="0.0135 -0.034 0" quat="0.707107 0.00732714 -0.707069 0" contype="0" priority="1" friction="0.6"/>
                    <geom name="right_foot2_collision" class="foot_capsule" size="0.01 0.10875" pos="0.01125 -0.02125 0" quat="0.707107 -0.00162553 -0.707105 0" contype="0" priority="1" friction="0.6"/>
                    <geom name="right_foot4_collision" class="foot_capsule" size="0.01 0.11025" pos="0.01175 -0.00675 0" quat="0.707107 0.00160341 -0.707105 0" contype="0" priority="1" friction="0.6"/>
                    <geom name="right_foot6_collision" class="foot_capsule" size="0.01 0.11025" pos="0.01175 0.00675 0" quat="0.707107 -0.00160341 -0.707105 0" contype="0" priority="1" friction="0.6"/>
                    <geom name="right_foot8_collision" class="foot_capsule" size="0.01 0.10875" pos="0.01125 0.02125 0" quat="0.707107 0.00162553 -0.707105 0" contype="0" priority="1" friction="0.6"/>
                    <geom name="right_foot10_collision" class="foot_capsule" size="0.01 0.0965052" pos="0.0135 0.034 0" quat="0.707107 -0.00732714 -0.707069 0" contype="0" priority="1" friction="0.6"/>
                    <body name="leg_right_ankle_link">
                      <geom name="leg_right_ankle_collision" class="collision" size="0.03 0.03" pos="-0.01 0 0.03" quat="0.707107 0 -0.707107 0" contype="0" conaffinity="0"/>
                      <geom name="leg_right_ankle_bar_collision" class="collision" size="0.03 0.035" pos="-0.045 0 0.05" quat="0.707107 0.707107 0 0" contype="0" conaffinity="0"/>
                    </body>
                  </body>
                </body>
              </body>
            </body>
            <body name="leg_right_femur_link" pos="0 -0.0669 -0.09" quat="0.819152 0 -0.573576 0">
              <inertial pos="0.0527475 0.000135688 -0.146959" quat="0.720223 -0.0942418 -0.0980078 0.680288" mass="3.94567" diaginertia="0.0121138 0.0118241 0.00184947"/>
              <joint name="leg_right_femur_joint" pos="0 0 0" axis="0 1 0" range="0.174533 1.22173"/>
              <geom class="visual" mesh="leg_femur_link"/>
              <geom name="leg_right_femur_collision" class="collision" size="0.0910718 0.2" pos="0.043456 0.000622273 -0.115825" quat="0.194464 0.00344037 0.980904 2.41185e-06" contype="0" conaffinity="0"/>
              <body name="leg_right_knee_link" pos="0.129945 0 -0.357092" quat="0.34202 0 0.939693 0">
                <inertial pos="-0.0569665 -5.4131e-05 -0.148821" quat="0.698616 0.0970713 0.0960701 0.702341" mass="1.02238" diaginertia="0.00215347 0.00207236 0.000258578"/>
                <joint name="leg_right_knee_joint" pos="0 0 0" axis="0 -1 0" range="0.349066 2.44346"/>
                <geom class="visual" mesh="leg_tibia_link"/>
                <geom name="leg_right_knee_collision" class="collision" size="0.04 0.18043" pos="-0.0456 0 -0.15165" quat="0.298159 0 -0.954516 0" contype="0" conaffinity="0"/>
                <geom name="leg_right_knee_bar_collision" class="collision" size="0.05 0.158114" pos="-0.1 0 -0.15" quat="0.987087 0 0.160182 0" contype="0" conaffinity="0"/>
              </body>
            </body>
          </body>
        </body>
      </body>
    </body>
  </worldbody>

  <contact>
    <exclude body1="leg_left_1_link" body2="leg_left_femur_link"/>
    <exclude body1="leg_left_ankle_link" body2="leg_left_knee_link"/>
    <exclude body1="leg_right_1_link" body2="leg_right_femur_link"/>
    <exclude body1="leg_right_ankle_link" body2="leg_right_knee_link"/>
  </contact>

  <equality>
    <connect name="leg_left_closed_kin_joint" body1="leg_left_4_link" body2="leg_left_knee_link" anchor="0 0 0" solref="0.004"/>
    <connect name="leg_right_closed_kin_joint" body1="leg_right_4_link" body2="leg_right_knee_link" anchor="0 0 0" solref="0.004"/>
  </equality>

  <actuator>
    <general name="leg_left_1_joint" joint="leg_left_1_joint" ctrllimited="false" ctrlrange="-1.0618 1.49813" forcelimited="true" forcerange="-80 80" biastype="affine" gainprm="100" biasprm="0 -100 -6.366"/>
    <general name="leg_right_1_joint" joint="leg_right_1_joint" ctrllimited="false" ctrlrange="-1.49813 1.0618" forcelimited="true" forcerange="-80 80" biastype="affine" gainprm="100" biasprm="0 -100 -6.366"/>
    <general name="leg_left_2_joint" joint="leg_left_2_joint" ctrllimited="false" ctrlrange="-3.04176 2.96322" forcelimited="true" forcerange="-230 230" biastype="affine" gainprm="100" biasprm="0 -100 -6.366"/>
    <general name="leg_right_2_joint" joint="leg_right_2_joint" ctrllimited="false" ctrlrange="-3.04176 2.96322" forcelimited="true" forcerange="-230 230" biastype="affine" gainprm="100" biasprm="0 -100 -6.366"/>
    <general name="leg_left_3_joint" joint="leg_left_3_joint" ctrllimited="false" ctrlrange="-1.86124 1.86124" forcelimited="true" forcerange="-139 139" biastype="affine" gainprm="100" biasprm="0 -100 -6.366"/>
    <general name="leg_right_3_joint" joint="leg_right_3_joint" ctrllimited="false" ctrlrange="-1.86124 1.86124" forcelimited="true" forcerange="-139 139" biastype="affine" gainprm="100" biasprm="0 -100 -6.366"/>
    <general name="leg_left_4_joint" joint="leg_left_4_joint" ctrllimited="false" ctrlrange="-5.40843 5.32989" forcelimited="true" forcerange="-140 140" biastype="affine" gainprm="30" biasprm="0 -30 -1.91"/>
    <general name="leg_right_4_joint" joint="leg_right_4_joint" ctrllimited="false" ctrlrange="-5.40843 5.32989" forcelimited="true" forcerange="-140 140" biastype="affine" gainprm="30" biasprm="0 -30 -1.91"/>
    <general name="leg_left_5_joint" joint="leg_left_5_joint" ctrllimited="false" ctrlrange="-3.20457 3.20457" forcelimited="true" forcerange="-82 82" biastype="affine" gainprm="30" biasprm="0 -30 -1.91"/>
    <general name="leg_right_5_joint" joint="leg_right_5_joint" ctrllimited="false" ctrlrange="-3.20457 3.20457" forcelimited="true" forcerange="-82 82" biastype="affine" gainprm="30" biasprm="0 -30 -1.91"/>
    <general name="leg_left_length_joint" joint="leg_left_length_joint" ctrllimited="false" ctrlrange="-0.555527 1.40167" forcelimited="true" forcerange="-1100 1100" biastype="affine" gainprm="1600" biasprm="0 -1600 -101.859"/>
    <general name="leg_right_length_joint" joint="leg_right_length_joint" ctrllimited="false" ctrlrange="-0.555527 1.40167" forcelimited="true" forcerange="-1100 1100" biastype="affine" gainprm="1600" biasprm="0 -1600 -101.859"/>
    <general name="pelvis_1_joint" joint="pelvis_1_joint" ctrllimited="false" ctrlrange="-1.35027 1.35027" forcelimited="true" forcerange="-50 50" biastype="affine" gainprm="49.94" biasprm="0 -49.94 -3.179"/>
    <general name="pelvis_2_joint" joint="pelvis_2_joint" ctrllimited="false" ctrlrange="-2.3102 2.3102" forcelimited="true" forcerange="-50 50" biastype="affine" gainprm="49.94" biasprm="0 -49.94 -3.179"/>
    <general name="arm_left_1_joint" joint="arm_left_1_joint" ctrllimited="false" ctrlrange="-3.61919 3.61919" forcelimited="true" forcerange="-50 50" biastype="affine" gainprm="49.94" biasprm="0 -49.94 -3.179"/>
    <general name="arm_left_2_joint" joint="arm_left_2_joint" ctrllimited="false" ctrlrange="-2.13566 3.44466" forcelimited="true" forcerange="-50 50" biastype="affine" gainprm="49.94" biasprm="0 -49.94 -3.179"/>
    <general name="arm_right_1_joint" joint="arm_right_1_joint" ctrllimited="false" ctrlrange="-3.61919 3.61919" forcelimited="true" forcerange="-50 50" biastype="affine" gainprm="49.94" biasprm="0 -49.94 -3.179"/>
    <general name="arm_right_2_joint" joint="arm_right_2_joint" ctrllimited="false" ctrlrange="-2.13566 3.44466" forcelimited="true" forcerange="-50 50" biastype="affine" gainprm="49.94" biasprm="0 -49.94 -3.179"/>
    <general name="arm_left_3_joint" joint="arm_left_3_joint" ctrllimited="false" ctrlrange="-3.57303 3.57303" forcelimited="true" forcerange="-25 25" biastype="affine" gainprm="26.177" biasprm="0 -26.177 -1.666"/>
    <general name="arm_left_4_joint" joint="arm_left_4_joint" ctrllimited="false" ctrlrange="-2.0895 3.3985" forcelimited="true" forcerange="-25 25" biastype="affine" gainprm="26.177" biasprm="0 -26.177 -1.666"/>
    <general name="arm_left_5_joint" joint="arm_left_5_joint" ctrllimited="false" ctrlrange="-3.57303 3.57303" forcelimited="true" forcerange="-25 25" biastype="affine" gainprm="26.177" biasprm="0 -26.177 -1.666"/>
    <general name="arm_right_3_joint" joint="arm_right_3_joint" ctrllimited="false" ctrlrange="-3.57303 3.57303" forcelimited="true" forcerange="-25 25" biastype="affine" gainprm="26.177" biasprm="0 -26.177 -1.666"/>
    <general name="arm_right_4_joint" joint="arm_right_4_joint" ctrllimited="false" ctrlrange="-2.0895 3.3985" forcelimited="true" forcerange="-25 25" biastype="affine" gainprm="26.177" biasprm="0 -26.177 -1.666"/>
    <general name="arm_right_5_joint" joint="arm_right_5_joint" ctrllimited="false" ctrlrange="-3.57303 3.57303" forcelimited="true" forcerange="-25 25" biastype="affine" gainprm="26.177" biasprm="0 -26.177 -1.666"/>
    <general name="arm_left_6_joint" joint="arm_left_6_joint" ctrllimited="false" ctrlrange="-2.84 3.95701" forcelimited="true" forcerange="-25 25" biastype="affine" gainprm="26.177" biasprm="0 -26.177 -1.666"/>
    <general name="arm_left_7_joint" joint="arm_left_7_joint" ctrllimited="false" ctrlrange="-3.57303 3.57303" forcelimited="true" forcerange="-25 25" biastype="affine" gainprm="26.177" biasprm="0 -26.177 -1.666"/>
    <general name="arm_right_6_joint" joint="arm_right_6_joint" ctrllimited="false" ctrlrange="-2.84 3.95701" forcelimited="true" forcerange="-25 25" biastype="affine" gainprm="26.177" biasprm="0 -26.177 -1.666"/>
    <general name="arm_right_7_joint" joint="arm_right_7_joint" ctrllimited="false" ctrlrange="-3.57303 3.57303" forcelimited="true" forcerange="-25 25" biastype="affine" gainprm="26.177" biasprm="0 -26.177 -1.666"/>
  </actuator>

  <sensor>
    <gyro site="imu" name="imu_ang_vel"/>
    <velocimeter site="imu" name="imu_lin_vel"/>
    <accelerometer site="imu" name="imu_lin_acc"/>
    <subtreeangmom body="base_link" name="root_angmom"/>
    <framequat objtype="site" objname="imu" name="imu_quat"/>
  </sensor>

  <keyframe>
    <key name="init_state" qpos="0 0 0.9 1 0 0 0 0 0 0.24 1.32 1.57 0.8 0 0 0 -0.24 1.32 -1.57 0.8 0 0 0 -0.012 0.054 0.04 0.6 -0.053 0 0.9 1.8 0.012 0.054 -0.04 0.6 -0.053 0 0.9 1.8" ctrl="-0.012 0.012 0.054 0.054 0.04 -0.04 -0.053 -0.053 0 0 0.6 0.6 0 0 0.24 1.32 -0.24 1.32 1.57 0.8 0 -1.57 0.8 0 0 0 0 0"/>
  </keyframe>
</mujoco>
